2022-01-17 12:09:40   Arguments: Namespace(upscale_input=False, downscale_input=False, augment_input='None', backbone='resnet50-conv4', use_netvlad=True, netvlad_clusters=64, use_gem=None, gem_p=3, gem_eps=1e-06, use_sgd=None, use_adagrad=None, momentum=0.9, train_batch_size=4, infer_batch_size=16, margin=0.1, epochs_num=20, patience=3, lr=1e-05, cache_refresh_rate=1000, queries_per_epoch=5000, negs_num_per_query=10, neg_samples_num=1000, seed=0, device='cuda', num_workers=12, val_positive_dist_threshold=25, train_positives_dist_threshold=10, recall_values=[1, 5, 10, 20], datasets_folder='./Dataset_pitts30k', exp_name='default', test_dataset_name=None, test_model_path=None, output_folder='runs/default/2022-01-17_12-09-40')
2022-01-17 12:09:40   The outputs are being saved in runs/default/2022-01-17_12-09-40
2022-01-17 12:09:40   Using 1 GPUs and 12 CPUs
2022-01-17 12:09:40   There are 96 queries without any positives within the training set. They won't be considered as they're useless for training.
2022-01-17 12:09:40   Train query set: < TripletsDataset, pitts30k - #database: 10000; #queries: 7320 >
2022-01-17 12:09:40   Val set: < BaseDataset, pitts30k - #database: 10000; #queries: 7608 >
2022-01-17 12:09:40   Test set: < BaseDataset, pitts30k - #database: 10000; #queries: 6816 >
2022-01-17 12:09:41   
Traceback (most recent call last):
  File "/home/franzhd/Aml_project/project_vg/run_train.py", line 47, in <module>
    model = network.GeoLocalizationNet(args)
  File "/home/franzhd/Aml_project/project_vg/network.py", line 31, in __init__
    with h5py.File(initcache, mode='r') as h5:
  File "/home/franzhd/.local/lib/python3.9/site-packages/h5py/_hl/files.py", line 507, in __init__
    fid = make_fid(name, mode, userblock_size, fapl, fcpl, swmr=swmr)
  File "/home/franzhd/.local/lib/python3.9/site-packages/h5py/_hl/files.py", line 220, in make_fid
    fid = h5f.open(name, flags, fapl=fapl)
  File "h5py/_objects.pyx", line 54, in h5py._objects.with_phil.wrapper
  File "h5py/_objects.pyx", line 55, in h5py._objects.with_phil.wrapper
  File "h5py/h5f.pyx", line 106, in h5py.h5f.open
FileNotFoundError: [Errno 2] Unable to open file (unable to open file: name = './Dataset_pitts30k/centroids_64_resnet50-conv4_desc_cen.hdf5', errno = 2, error message = 'No such file or directory', flags = 0, o_flags = 0)

