2022-01-05 18:21:51   Arguments: Namespace(cache_refresh_rate=1000, datasets_folder='./', device='cuda', epochs_num=5, exp_name='default', infer_batch_size=16, lr=1e-05, margin=0.1, neg_samples_num=1000, negs_num_per_query=10, netvlad_clusters=64, num_workers=8, output_folder='runs/default/2022-01-05_18-21-51', patience=3, queries_per_epoch=5000, recall_values=[1, 5, 10, 20], seed=0, train_batch_size=4, train_positives_dist_threshold=10, use_netvlad=True, val_positive_dist_threshold=25)
2022-01-05 18:21:51   The outputs are being saved in runs/default/2022-01-05_18-21-51
2022-01-05 18:21:51   Using 1 GPUs and 6 CPUs
2022-01-05 18:21:51   Loading dataset Pitts30k from folder ./
2022-01-05 18:21:51   
Traceback (most recent call last):
  File "project_vg/train.py", line 34, in <module>
    triplets_ds = datasets_ws.TripletsDataset(args, args.datasets_folder, "pitts30k", "train", args.negs_num_per_query)
  File "/mnt/batch/tasks/shared/LS_root/mounts/clusters/aml-train/code/Users/S285913/project_vg/datasets_ws.py", line 106, in __init__
    super().__init__(args, datasets_folder, dataset_name, split)
  File "/mnt/batch/tasks/shared/LS_root/mounts/clusters/aml-train/code/Users/S285913/project_vg/datasets_ws.py", line 60, in __init__
    if not os.path.exists(self.dataset_folder): raise FileNotFoundError(f"Folder {self.dataset_folder} does not exist")
FileNotFoundError: Folder ./pitts30k/images/train does not exist

